 * Serving Flask app 'app'
 * Debug mode: off
WARNING: This is a development server. Do not use it in a production deployment. Use a production WSGI server instead.
 * Running on http://127.0.0.1:5000
Press CTRL+C to quit
127.0.0.1 - - [30/Nov/2023 00:54:48] "GET / HTTP/1.0" 200 -
127.0.0.1 - - [30/Nov/2023 00:54:48] "GET /favicon.ico HTTP/1.0" 404 -
127.0.0.1 - - [30/Nov/2023 00:56:22] "GET / HTTP/1.0" 200 -
[2023-11-30 20:14:31 +0000] [42918] [INFO] Starting gunicorn 21.2.0
[2023-11-30 20:14:31 +0000] [42918] [INFO] Listening at: http://127.0.0.1:8000 (42918)
[2023-11-30 20:14:31 +0000] [42918] [INFO] Using worker: sync
[2023-11-30 20:14:31 +0000] [42920] [INFO] Booting worker with pid: 42920
[2023-11-30 20:14:31 +0000] [42921] [INFO] Booting worker with pid: 42921
[2023-11-30 20:14:31 +0000] [42922] [INFO] Booting worker with pid: 42922
[2023-11-30 20:14:31 +0000] [42923] [INFO] Booting worker with pid: 42923
[2023-11-30 20:17:56 +0000] [42940] [INFO] Starting gunicorn 21.2.0
[2023-11-30 20:17:56 +0000] [42940] [INFO] Listening at: http://127.0.0.1:5000 (42940)
[2023-11-30 20:17:56 +0000] [42940] [INFO] Using worker: sync
[2023-11-30 20:17:56 +0000] [42942] [INFO] Booting worker with pid: 42942
[2023-11-30 20:17:56 +0000] [42943] [INFO] Booting worker with pid: 42943
[2023-11-30 20:17:56 +0000] [42944] [INFO] Booting worker with pid: 42944
[2023-11-30 20:17:56 +0000] [42945] [INFO] Booting worker with pid: 42945
[2023-11-30 20:24:45 +0000] [43437] [INFO] Starting gunicorn 21.2.0
[2023-11-30 20:24:45 +0000] [43437] [INFO] Listening at: http://0.0.0.0:5000 (43437)
[2023-11-30 20:24:45 +0000] [43437] [INFO] Using worker: sync
[2023-11-30 20:24:45 +0000] [43439] [INFO] Booting worker with pid: 43439
[2023-11-30 20:24:45 +0000] [43440] [INFO] Booting worker with pid: 43440
[2023-11-30 20:24:45 +0000] [43441] [INFO] Booting worker with pid: 43441
[2023-11-30 20:24:45 +0000] [43442] [INFO] Booting worker with pid: 43442
[2023-11-30 20:27:37 +0000] [43439] [WARNING] Invalid request from ip=99.228.120.169: Invalid HTTP method: '\x16\x03\x01\x02\x16\x01\x00\x02\x12\x03\x03.$µ\x10FL³©¦X\x08ù"F«\x9du\x07[\x82¸/\x92¢\x96\x195\x07b^'
[2023-11-30 20:28:15,173] ERROR in app: Exception on /login [POST]
Traceback (most recent call last):
  File "/usr/local/lib/python3.8/dist-packages/flask/app.py", line 1455, in wsgi_app
    response = self.full_dispatch_request()
  File "/usr/local/lib/python3.8/dist-packages/flask/app.py", line 869, in full_dispatch_request
    rv = self.handle_user_exception(e)
  File "/usr/local/lib/python3.8/dist-packages/flask/app.py", line 867, in full_dispatch_request
    rv = self.dispatch_request()
  File "/usr/local/lib/python3.8/dist-packages/flask/app.py", line 852, in dispatch_request
    return self.ensure_sync(self.view_functions[rule.endpoint])(**view_args)
  File "/home/ammo/public/app.py", line 30, in login
    cursor.execute('SELECT * FROM users WHERE username=%s', (username,))
  File "/usr/local/lib/python3.8/dist-packages/mysql/connector/cursor.py", line 617, in execute
    self._handle_result(self._connection.cmd_query(stmt))
  File "/usr/local/lib/python3.8/dist-packages/mysql/connector/opentelemetry/context_propagation.py", line 77, in wrapper
    return method(cnx, *args, **kwargs)
  File "/usr/local/lib/python3.8/dist-packages/mysql/connector/connection.py", line 843, in cmd_query
    result = self._handle_result(self._send_cmd(ServerCmd.QUERY, query))
  File "/usr/local/lib/python3.8/dist-packages/mysql/connector/connection.py", line 620, in _handle_result
    raise get_exception(packet)
mysql.connector.errors.ProgrammingError: 1146 (42S02): Table 'user.users' doesn't exist
[2023-11-30 20:28:45 +0000] [43437] [CRITICAL] WORKER TIMEOUT (pid:43440)
[2023-11-30 20:28:45 +0000] [43440] [INFO] Worker exiting (pid: 43440)
[2023-11-30 20:28:45 +0000] [43437] [ERROR] Worker (pid:43440) exited with code 1
[2023-11-30 20:28:45 +0000] [43437] [ERROR] Worker (pid:43440) exited with code 1.
[2023-11-30 20:28:45 +0000] [43952] [INFO] Booting worker with pid: 43952
[2023-11-30 20:28:51 +0000] [43437] [CRITICAL] WORKER TIMEOUT (pid:43439)
[2023-11-30 20:28:51 +0000] [43439] [INFO] Worker exiting (pid: 43439)
[2023-11-30 20:28:51 +0000] [43437] [ERROR] Worker (pid:43439) exited with code 1
[2023-11-30 20:28:51 +0000] [43437] [ERROR] Worker (pid:43439) exited with code 1.
[2023-11-30 20:28:51 +0000] [43953] [INFO] Booting worker with pid: 43953
[2023-11-30 21:16:58 +0000] [45686] [INFO] Starting gunicorn 21.2.0
[2023-11-30 21:16:58 +0000] [45686] [INFO] Listening at: http://127.0.0.1:5000 (45686)
[2023-11-30 21:16:58 +0000] [45686] [INFO] Using worker: sync
[2023-11-30 21:16:58 +0000] [45688] [INFO] Booting worker with pid: 45688
[2023-11-30 21:16:58 +0000] [45689] [INFO] Booting worker with pid: 45689
[2023-11-30 21:16:58 +0000] [45690] [INFO] Booting worker with pid: 45690
[2023-11-30 21:16:58 +0000] [45691] [INFO] Booting worker with pid: 45691
[2023-11-30 21:17:56,433] ERROR in app: Exception on /login [POST]
Traceback (most recent call last):
  File "/usr/local/lib/python3.8/dist-packages/flask/app.py", line 1455, in wsgi_app
    response = self.full_dispatch_request()
  File "/usr/local/lib/python3.8/dist-packages/flask/app.py", line 869, in full_dispatch_request
    rv = self.handle_user_exception(e)
  File "/usr/local/lib/python3.8/dist-packages/flask/app.py", line 867, in full_dispatch_request
    rv = self.dispatch_request()
  File "/usr/local/lib/python3.8/dist-packages/flask/app.py", line 852, in dispatch_request
    return self.ensure_sync(self.view_functions[rule.endpoint])(**view_args)
  File "/home/ammo/public/app.py", line 30, in login
    cursor.execute('SELECT * FROM users WHERE username=%s', (username,))
  File "/usr/local/lib/python3.8/dist-packages/mysql/connector/cursor.py", line 617, in execute
    self._handle_result(self._connection.cmd_query(stmt))
  File "/usr/local/lib/python3.8/dist-packages/mysql/connector/opentelemetry/context_propagation.py", line 77, in wrapper
    return method(cnx, *args, **kwargs)
  File "/usr/local/lib/python3.8/dist-packages/mysql/connector/connection.py", line 843, in cmd_query
    result = self._handle_result(self._send_cmd(ServerCmd.QUERY, query))
  File "/usr/local/lib/python3.8/dist-packages/mysql/connector/connection.py", line 620, in _handle_result
    raise get_exception(packet)
mysql.connector.errors.ProgrammingError: 1146 (42S02): Table 'user.users' doesn't exist
[2023-11-30 21:24:18,311] ERROR in app: Exception on /login [POST]
Traceback (most recent call last):
  File "/usr/local/lib/python3.8/dist-packages/flask/app.py", line 1455, in wsgi_app
    response = self.full_dispatch_request()
  File "/usr/local/lib/python3.8/dist-packages/flask/app.py", line 869, in full_dispatch_request
    rv = self.handle_user_exception(e)
  File "/usr/local/lib/python3.8/dist-packages/flask/app.py", line 867, in full_dispatch_request
    rv = self.dispatch_request()
  File "/usr/local/lib/python3.8/dist-packages/flask/app.py", line 852, in dispatch_request
    return self.ensure_sync(self.view_functions[rule.endpoint])(**view_args)
  File "/home/ammo/public/app.py", line 30, in login
    CREATE TABLE IF NOT EXISTS users (
  File "/usr/local/lib/python3.8/dist-packages/mysql/connector/cursor.py", line 617, in execute
    self._handle_result(self._connection.cmd_query(stmt))
  File "/usr/local/lib/python3.8/dist-packages/mysql/connector/opentelemetry/context_propagation.py", line 77, in wrapper
    return method(cnx, *args, **kwargs)
  File "/usr/local/lib/python3.8/dist-packages/mysql/connector/connection.py", line 843, in cmd_query
    result = self._handle_result(self._send_cmd(ServerCmd.QUERY, query))
  File "/usr/local/lib/python3.8/dist-packages/mysql/connector/connection.py", line 620, in _handle_result
    raise get_exception(packet)
mysql.connector.errors.ProgrammingError: 1146 (42S02): Table 'user.users' doesn't exist
[2023-11-30 21:28:11,065] ERROR in app: Exception on /login [GET]
Traceback (most recent call last):
  File "/usr/local/lib/python3.8/dist-packages/flask/app.py", line 1455, in wsgi_app
    response = self.full_dispatch_request()
  File "/usr/local/lib/python3.8/dist-packages/flask/app.py", line 869, in full_dispatch_request
    rv = self.handle_user_exception(e)
  File "/usr/local/lib/python3.8/dist-packages/flask/app.py", line 867, in full_dispatch_request
    rv = self.dispatch_request()
  File "/usr/local/lib/python3.8/dist-packages/flask/app.py", line 852, in dispatch_request
    return self.ensure_sync(self.view_functions[rule.endpoint])(**view_args)
  File "/home/ammo/public/app.py", line 40, in login
    password VARCHAR(255) NOT NULL
  File "/usr/local/lib/python3.8/dist-packages/flask/templating.py", line 152, in render_template
    return _render(app, template, context)
  File "/usr/local/lib/python3.8/dist-packages/flask/templating.py", line 133, in _render
    rv = template.render(context)
  File "/usr/local/lib/python3.8/dist-packages/jinja2/environment.py", line 1301, in render
    self.environment.handle_exception()
  File "/usr/local/lib/python3.8/dist-packages/jinja2/environment.py", line 936, in handle_exception
    raise rewrite_traceback_stack(source=source)
  File "/home/ammo/public/templates/login.html", line 19, in top-level template code
    <form method="post" action="{{ url_for('register') }}">
  File "/usr/local/lib/python3.8/dist-packages/flask/app.py", line 1071, in url_for
    return self.handle_url_build_error(error, endpoint, values)
  File "/usr/local/lib/python3.8/dist-packages/flask/app.py", line 1060, in url_for
    rv = url_adapter.build(  # type: ignore[union-attr]
  File "/usr/local/lib/python3.8/dist-packages/werkzeug/routing/map.py", line 919, in build
    raise BuildError(endpoint, values, method, self)
werkzeug.routing.exceptions.BuildError: Could not build url for endpoint 'register'. Did you mean 'login' instead?
[2023-11-30 21:28:13,943] ERROR in app: Exception on /login [GET]
Traceback (most recent call last):
  File "/usr/local/lib/python3.8/dist-packages/flask/app.py", line 1455, in wsgi_app
    response = self.full_dispatch_request()
  File "/usr/local/lib/python3.8/dist-packages/flask/app.py", line 869, in full_dispatch_request
    rv = self.handle_user_exception(e)
  File "/usr/local/lib/python3.8/dist-packages/flask/app.py", line 867, in full_dispatch_request
    rv = self.dispatch_request()
  File "/usr/local/lib/python3.8/dist-packages/flask/app.py", line 852, in dispatch_request
    return self.ensure_sync(self.view_functions[rule.endpoint])(**view_args)
  File "/home/ammo/public/app.py", line 40, in login
    password VARCHAR(255) NOT NULL
  File "/usr/local/lib/python3.8/dist-packages/flask/templating.py", line 152, in render_template
    return _render(app, template, context)
  File "/usr/local/lib/python3.8/dist-packages/flask/templating.py", line 133, in _render
    rv = template.render(context)
  File "/usr/local/lib/python3.8/dist-packages/jinja2/environment.py", line 1301, in render
    self.environment.handle_exception()
  File "/usr/local/lib/python3.8/dist-packages/jinja2/environment.py", line 936, in handle_exception
    raise rewrite_traceback_stack(source=source)
  File "/home/ammo/public/templates/login.html", line 19, in top-level template code
    <form method="post" action="{{ url_for('register') }}">
  File "/usr/local/lib/python3.8/dist-packages/flask/app.py", line 1071, in url_for
    return self.handle_url_build_error(error, endpoint, values)
  File "/usr/local/lib/python3.8/dist-packages/flask/app.py", line 1060, in url_for
    rv = url_adapter.build(  # type: ignore[union-attr]
  File "/usr/local/lib/python3.8/dist-packages/werkzeug/routing/map.py", line 919, in build
    raise BuildError(endpoint, values, method, self)
werkzeug.routing.exceptions.BuildError: Could not build url for endpoint 'register'. Did you mean 'login' instead?
[2023-11-30 21:28:30,233] ERROR in app: Exception on /login [POST]
Traceback (most recent call last):
  File "/usr/local/lib/python3.8/dist-packages/flask/app.py", line 1455, in wsgi_app
    response = self.full_dispatch_request()
  File "/usr/local/lib/python3.8/dist-packages/flask/app.py", line 869, in full_dispatch_request
    rv = self.handle_user_exception(e)
  File "/usr/local/lib/python3.8/dist-packages/flask/app.py", line 867, in full_dispatch_request
    rv = self.dispatch_request()
  File "/usr/local/lib/python3.8/dist-packages/flask/app.py", line 852, in dispatch_request
    return self.ensure_sync(self.view_functions[rule.endpoint])(**view_args)
  File "/home/ammo/public/app.py", line 30, in login
    return cursor.fetchone()
  File "/usr/local/lib/python3.8/dist-packages/mysql/connector/cursor.py", line 617, in execute
    self._handle_result(self._connection.cmd_query(stmt))
  File "/usr/local/lib/python3.8/dist-packages/mysql/connector/opentelemetry/context_propagation.py", line 77, in wrapper
    return method(cnx, *args, **kwargs)
  File "/usr/local/lib/python3.8/dist-packages/mysql/connector/connection.py", line 843, in cmd_query
    result = self._handle_result(self._send_cmd(ServerCmd.QUERY, query))
  File "/usr/local/lib/python3.8/dist-packages/mysql/connector/connection.py", line 620, in _handle_result
    raise get_exception(packet)
mysql.connector.errors.ProgrammingError: 1146 (42S02): Table 'user.users' doesn't exist
[2023-11-30 21:29:45 +0000] [45731] [INFO] Starting gunicorn 21.2.0
[2023-11-30 21:29:45 +0000] [45731] [INFO] Listening at: http://127.0.0.1:5000 (45731)
[2023-11-30 21:29:45 +0000] [45731] [INFO] Using worker: sync
[2023-11-30 21:29:45 +0000] [45733] [INFO] Booting worker with pid: 45733
[2023-11-30 21:29:45 +0000] [45734] [INFO] Booting worker with pid: 45734
[2023-11-30 21:29:45 +0000] [45735] [INFO] Booting worker with pid: 45735
[2023-11-30 21:29:45 +0000] [45736] [INFO] Booting worker with pid: 45736
[2023-11-30 21:29:45 +0000] [45733] [ERROR] Exception in worker process
Traceback (most recent call last):
  File "/usr/local/lib/python3.8/dist-packages/gunicorn/arbiter.py", line 609, in spawn_worker
    worker.init_process()
  File "/usr/local/lib/python3.8/dist-packages/gunicorn/workers/base.py", line 134, in init_process
    self.load_wsgi()
  File "/usr/local/lib/python3.8/dist-packages/gunicorn/workers/base.py", line 146, in load_wsgi
    self.wsgi = self.app.wsgi()
  File "/usr/local/lib/python3.8/dist-packages/gunicorn/app/base.py", line 67, in wsgi
    self.callable = self.load()
  File "/usr/local/lib/python3.8/dist-packages/gunicorn/app/wsgiapp.py", line 58, in load
    return self.load_wsgiapp()
  File "/usr/local/lib/python3.8/dist-packages/gunicorn/app/wsgiapp.py", line 48, in load_wsgiapp
    return util.import_app(self.app_uri)
  File "/usr/local/lib/python3.8/dist-packages/gunicorn/util.py", line 371, in import_app
    mod = importlib.import_module(module)
  File "/usr/lib/python3.8/importlib/__init__.py", line 127, in import_module
    return _bootstrap._gcd_import(name[level:], package, level)
  File "<frozen importlib._bootstrap>", line 1014, in _gcd_import
  File "<frozen importlib._bootstrap>", line 991, in _find_and_load
  File "<frozen importlib._bootstrap>", line 975, in _find_and_load_unlocked
  File "<frozen importlib._bootstrap>", line 671, in _load_unlocked
  File "<frozen importlib._bootstrap_external>", line 848, in exec_module
  File "<frozen importlib._bootstrap>", line 219, in _call_with_frames_removed
  File "/home/ammo/public/app.py", line 36, in <module>
    execute_query('''
  File "/home/ammo/public/app.py", line 25, in execute_query
    with mysql.connector.connect(**db_config) as connection:
NameError: name 'db_config' is not defined
[2023-11-30 21:29:45 +0000] [45733] [INFO] Worker exiting (pid: 45733)
[2023-11-30 21:29:45 +0000] [45734] [ERROR] Exception in worker process
Traceback (most recent call last):
  File "/usr/local/lib/python3.8/dist-packages/gunicorn/arbiter.py", line 609, in spawn_worker
    worker.init_process()
  File "/usr/local/lib/python3.8/dist-packages/gunicorn/workers/base.py", line 134, in init_process
    self.load_wsgi()
  File "/usr/local/lib/python3.8/dist-packages/gunicorn/workers/base.py", line 146, in load_wsgi
    self.wsgi = self.app.wsgi()
  File "/usr/local/lib/python3.8/dist-packages/gunicorn/app/base.py", line 67, in wsgi
    self.callable = self.load()
  File "/usr/local/lib/python3.8/dist-packages/gunicorn/app/wsgiapp.py", line 58, in load
    return self.load_wsgiapp()
  File "/usr/local/lib/python3.8/dist-packages/gunicorn/app/wsgiapp.py", line 48, in load_wsgiapp
    return util.import_app(self.app_uri)
  File "/usr/local/lib/python3.8/dist-packages/gunicorn/util.py", line 371, in import_app
    mod = importlib.import_module(module)
  File "/usr/lib/python3.8/importlib/__init__.py", line 127, in import_module
    return _bootstrap._gcd_import(name[level:], package, level)
  File "<frozen importlib._bootstrap>", line 1014, in _gcd_import
  File "<frozen importlib._bootstrap>", line 991, in _find_and_load
  File "<frozen importlib._bootstrap>", line 975, in _find_and_load_unlocked
  File "<frozen importlib._bootstrap>", line 671, in _load_unlocked
  File "<frozen importlib._bootstrap_external>", line 848, in exec_module
  File "<frozen importlib._bootstrap>", line 219, in _call_with_frames_removed
  File "/home/ammo/public/app.py", line 36, in <module>
    execute_query('''
  File "/home/ammo/public/app.py", line 25, in execute_query
    with mysql.connector.connect(**db_config) as connection:
NameError: name 'db_config' is not defined
[2023-11-30 21:29:45 +0000] [45734] [INFO] Worker exiting (pid: 45734)
[2023-11-30 21:29:46 +0000] [45735] [ERROR] Exception in worker process
Traceback (most recent call last):
  File "/usr/local/lib/python3.8/dist-packages/gunicorn/arbiter.py", line 609, in spawn_worker
    worker.init_process()
  File "/usr/local/lib/python3.8/dist-packages/gunicorn/workers/base.py", line 134, in init_process
    self.load_wsgi()
  File "/usr/local/lib/python3.8/dist-packages/gunicorn/workers/base.py", line 146, in load_wsgi
    self.wsgi = self.app.wsgi()
  File "/usr/local/lib/python3.8/dist-packages/gunicorn/app/base.py", line 67, in wsgi
    self.callable = self.load()
  File "/usr/local/lib/python3.8/dist-packages/gunicorn/app/wsgiapp.py", line 58, in load
    return self.load_wsgiapp()
  File "/usr/local/lib/python3.8/dist-packages/gunicorn/app/wsgiapp.py", line 48, in load_wsgiapp
    return util.import_app(self.app_uri)
  File "/usr/local/lib/python3.8/dist-packages/gunicorn/util.py", line 371, in import_app
    mod = importlib.import_module(module)
  File "/usr/lib/python3.8/importlib/__init__.py", line 127, in import_module
    return _bootstrap._gcd_import(name[level:], package, level)
  File "<frozen importlib._bootstrap>", line 1014, in _gcd_import
  File "<frozen importlib._bootstrap>", line 991, in _find_and_load
  File "<frozen importlib._bootstrap>", line 975, in _find_and_load_unlocked
  File "<frozen importlib._bootstrap>", line 671, in _load_unlocked
  File "<frozen importlib._bootstrap_external>", line 848, in exec_module
  File "<frozen importlib._bootstrap>", line 219, in _call_with_frames_removed
  File "/home/ammo/public/app.py", line 36, in <module>
    execute_query('''
  File "/home/ammo/public/app.py", line 25, in execute_query
    with mysql.connector.connect(**db_config) as connection:
NameError: name 'db_config' is not defined
[2023-11-30 21:29:46 +0000] [45735] [INFO] Worker exiting (pid: 45735)
[2023-11-30 21:29:46 +0000] [45736] [ERROR] Exception in worker process
Traceback (most recent call last):
  File "/usr/local/lib/python3.8/dist-packages/gunicorn/arbiter.py", line 609, in spawn_worker
    worker.init_process()
  File "/usr/local/lib/python3.8/dist-packages/gunicorn/workers/base.py", line 134, in init_process
    self.load_wsgi()
  File "/usr/local/lib/python3.8/dist-packages/gunicorn/workers/base.py", line 146, in load_wsgi
    self.wsgi = self.app.wsgi()
  File "/usr/local/lib/python3.8/dist-packages/gunicorn/app/base.py", line 67, in wsgi
    self.callable = self.load()
  File "/usr/local/lib/python3.8/dist-packages/gunicorn/app/wsgiapp.py", line 58, in load
    return self.load_wsgiapp()
  File "/usr/local/lib/python3.8/dist-packages/gunicorn/app/wsgiapp.py", line 48, in load_wsgiapp
    return util.import_app(self.app_uri)
  File "/usr/local/lib/python3.8/dist-packages/gunicorn/util.py", line 371, in import_app
    mod = importlib.import_module(module)
  File "/usr/lib/python3.8/importlib/__init__.py", line 127, in import_module
    return _bootstrap._gcd_import(name[level:], package, level)
  File "<frozen importlib._bootstrap>", line 1014, in _gcd_import
  File "<frozen importlib._bootstrap>", line 991, in _find_and_load
  File "<frozen importlib._bootstrap>", line 975, in _find_and_load_unlocked
  File "<frozen importlib._bootstrap>", line 671, in _load_unlocked
  File "<frozen importlib._bootstrap_external>", line 848, in exec_module
  File "<frozen importlib._bootstrap>", line 219, in _call_with_frames_removed
  File "/home/ammo/public/app.py", line 36, in <module>
    execute_query('''
  File "/home/ammo/public/app.py", line 25, in execute_query
    with mysql.connector.connect(**db_config) as connection:
NameError: name 'db_config' is not defined
[2023-11-30 21:29:46 +0000] [45736] [INFO] Worker exiting (pid: 45736)
[2023-11-30 21:29:46 +0000] [45731] [ERROR] Worker (pid:45733) exited with code 3
[2023-11-30 21:29:46 +0000] [45731] [ERROR] Worker (pid:45735) was sent SIGTERM!
[2023-11-30 21:29:46 +0000] [45731] [ERROR] Worker (pid:45734) was sent SIGTERM!
[2023-11-30 21:29:46 +0000] [45731] [ERROR] Worker (pid:45736) exited with code 3
Traceback (most recent call last):
  File "/usr/local/lib/python3.8/dist-packages/gunicorn/arbiter.py", line 209, in run
    self.sleep()
  File "/usr/local/lib/python3.8/dist-packages/gunicorn/arbiter.py", line 360, in sleep
    ready = select.select([self.PIPE[0]], [], [], 1.0)
  File "/usr/local/lib/python3.8/dist-packages/gunicorn/arbiter.py", line 242, in handle_chld
    self.reap_workers()
  File "/usr/local/lib/python3.8/dist-packages/gunicorn/arbiter.py", line 530, in reap_workers
    raise HaltServer(reason, self.WORKER_BOOT_ERROR)
gunicorn.errors.HaltServer: <HaltServer 'Worker failed to boot.' 3>

During handling of the above exception, another exception occurred:

Traceback (most recent call last):
  File "/usr/local/bin/gunicorn", line 8, in <module>
    sys.exit(run())
  File "/usr/local/lib/python3.8/dist-packages/gunicorn/app/wsgiapp.py", line 67, in run
    WSGIApplication("%(prog)s [OPTIONS] [APP_MODULE]").run()
  File "/usr/local/lib/python3.8/dist-packages/gunicorn/app/base.py", line 236, in run
    super().run()
  File "/usr/local/lib/python3.8/dist-packages/gunicorn/app/base.py", line 72, in run
    Arbiter(self).run()
  File "/usr/local/lib/python3.8/dist-packages/gunicorn/arbiter.py", line 229, in run
    self.halt(reason=inst.reason, exit_status=inst.exit_status)
  File "/usr/local/lib/python3.8/dist-packages/gunicorn/arbiter.py", line 342, in halt
    self.stop()
  File "/usr/local/lib/python3.8/dist-packages/gunicorn/arbiter.py", line 396, in stop
    time.sleep(0.1)
  File "/usr/local/lib/python3.8/dist-packages/gunicorn/arbiter.py", line 242, in handle_chld
    self.reap_workers()
  File "/usr/local/lib/python3.8/dist-packages/gunicorn/arbiter.py", line 530, in reap_workers
    raise HaltServer(reason, self.WORKER_BOOT_ERROR)
gunicorn.errors.HaltServer: <HaltServer 'Worker failed to boot.' 3>
[2023-11-30 21:30:06 +0000] [45739] [INFO] Starting gunicorn 21.2.0
[2023-11-30 21:30:06 +0000] [45739] [INFO] Listening at: http://127.0.0.1:5000 (45739)
[2023-11-30 21:30:06 +0000] [45739] [INFO] Using worker: sync
[2023-11-30 21:30:06 +0000] [45741] [INFO] Booting worker with pid: 45741
[2023-11-30 21:30:06 +0000] [45742] [INFO] Booting worker with pid: 45742
[2023-11-30 21:30:06 +0000] [45743] [INFO] Booting worker with pid: 45743
[2023-11-30 21:30:06 +0000] [45744] [INFO] Booting worker with pid: 45744
[2023-11-30 21:30:06 +0000] [45741] [ERROR] Exception in worker process
Traceback (most recent call last):
  File "/usr/local/lib/python3.8/dist-packages/gunicorn/arbiter.py", line 609, in spawn_worker
    worker.init_process()
  File "/usr/local/lib/python3.8/dist-packages/gunicorn/workers/base.py", line 134, in init_process
    self.load_wsgi()
  File "/usr/local/lib/python3.8/dist-packages/gunicorn/workers/base.py", line 146, in load_wsgi
    self.wsgi = self.app.wsgi()
  File "/usr/local/lib/python3.8/dist-packages/gunicorn/app/base.py", line 67, in wsgi
    self.callable = self.load()
  File "/usr/local/lib/python3.8/dist-packages/gunicorn/app/wsgiapp.py", line 58, in load
    return self.load_wsgiapp()
  File "/usr/local/lib/python3.8/dist-packages/gunicorn/app/wsgiapp.py", line 48, in load_wsgiapp
    return util.import_app(self.app_uri)
  File "/usr/local/lib/python3.8/dist-packages/gunicorn/util.py", line 371, in import_app
    mod = importlib.import_module(module)
  File "/usr/lib/python3.8/importlib/__init__.py", line 127, in import_module
    return _bootstrap._gcd_import(name[level:], package, level)
  File "<frozen importlib._bootstrap>", line 1014, in _gcd_import
  File "<frozen importlib._bootstrap>", line 991, in _find_and_load
  File "<frozen importlib._bootstrap>", line 975, in _find_and_load_unlocked
  File "<frozen importlib._bootstrap>", line 671, in _load_unlocked
  File "<frozen importlib._bootstrap_external>", line 848, in exec_module
  File "<frozen importlib._bootstrap>", line 219, in _call_with_frames_removed
  File "/home/ammo/public/app.py", line 36, in <module>
    execute_query('''
  File "/home/ammo/public/app.py", line 25, in execute_query
    with mysql.connector.connect(**db_config) as connection:
NameError: name 'db_config' is not defined
[2023-11-30 21:30:06 +0000] [45741] [INFO] Worker exiting (pid: 45741)
[2023-11-30 21:30:07 +0000] [45742] [ERROR] Exception in worker process
Traceback (most recent call last):
  File "/usr/local/lib/python3.8/dist-packages/gunicorn/arbiter.py", line 609, in spawn_worker
    worker.init_process()
  File "/usr/local/lib/python3.8/dist-packages/gunicorn/workers/base.py", line 134, in init_process
    self.load_wsgi()
  File "/usr/local/lib/python3.8/dist-packages/gunicorn/workers/base.py", line 146, in load_wsgi
    self.wsgi = self.app.wsgi()
  File "/usr/local/lib/python3.8/dist-packages/gunicorn/app/base.py", line 67, in wsgi
    self.callable = self.load()
  File "/usr/local/lib/python3.8/dist-packages/gunicorn/app/wsgiapp.py", line 58, in load
    return self.load_wsgiapp()
  File "/usr/local/lib/python3.8/dist-packages/gunicorn/app/wsgiapp.py", line 48, in load_wsgiapp
    return util.import_app(self.app_uri)
  File "/usr/local/lib/python3.8/dist-packages/gunicorn/util.py", line 371, in import_app
    mod = importlib.import_module(module)
  File "/usr/lib/python3.8/importlib/__init__.py", line 127, in import_module
    return _bootstrap._gcd_import(name[level:], package, level)
  File "<frozen importlib._bootstrap>", line 1014, in _gcd_import
  File "<frozen importlib._bootstrap>", line 991, in _find_and_load
  File "<frozen importlib._bootstrap>", line 975, in _find_and_load_unlocked
  File "<frozen importlib._bootstrap>", line 671, in _load_unlocked
  File "<frozen importlib._bootstrap_external>", line 848, in exec_module
  File "<frozen importlib._bootstrap>", line 219, in _call_with_frames_removed
  File "/home/ammo/public/app.py", line 36, in <module>
    execute_query('''
  File "/home/ammo/public/app.py", line 25, in execute_query
    with mysql.connector.connect(**db_config) as connection:
NameError: name 'db_config' is not defined
[2023-11-30 21:30:07 +0000] [45742] [INFO] Worker exiting (pid: 45742)
[2023-11-30 21:30:07 +0000] [45739] [ERROR] Worker (pid:45741) exited with code 3
[2023-11-30 21:30:07 +0000] [45739] [ERROR] Worker (pid:45742) was sent SIGTERM!
[2023-11-30 21:30:07 +0000] [45743] [ERROR] Exception in worker process
Traceback (most recent call last):
  File "/usr/local/lib/python3.8/dist-packages/gunicorn/arbiter.py", line 609, in spawn_worker
    worker.init_process()
  File "/usr/local/lib/python3.8/dist-packages/gunicorn/workers/base.py", line 134, in init_process
    self.load_wsgi()
  File "/usr/local/lib/python3.8/dist-packages/gunicorn/workers/base.py", line 146, in load_wsgi
    self.wsgi = self.app.wsgi()
  File "/usr/local/lib/python3.8/dist-packages/gunicorn/app/base.py", line 67, in wsgi
    self.callable = self.load()
  File "/usr/local/lib/python3.8/dist-packages/gunicorn/app/wsgiapp.py", line 58, in load
    return self.load_wsgiapp()
  File "/usr/local/lib/python3.8/dist-packages/gunicorn/app/wsgiapp.py", line 48, in load_wsgiapp
    return util.import_app(self.app_uri)
  File "/usr/local/lib/python3.8/dist-packages/gunicorn/util.py", line 371, in import_app
    mod = importlib.import_module(module)
  File "/usr/lib/python3.8/importlib/__init__.py", line 127, in import_module
    return _bootstrap._gcd_import(name[level:], package, level)
  File "<frozen importlib._bootstrap>", line 1014, in _gcd_import
  File "<frozen importlib._bootstrap>", line 991, in _find_and_load
  File "<frozen importlib._bootstrap>", line 975, in _find_and_load_unlocked
  File "<frozen importlib._bootstrap>", line 671, in _load_unlocked
  File "<frozen importlib._bootstrap_external>", line 848, in exec_module
  File "<frozen importlib._bootstrap>", line 219, in _call_with_frames_removed
  File "/home/ammo/public/app.py", line 36, in <module>
    execute_query('''
  File "/home/ammo/public/app.py", line 25, in execute_query
    with mysql.connector.connect(**db_config) as connection:
NameError: name 'db_config' is not defined
[2023-11-30 21:30:07 +0000] [45743] [INFO] Worker exiting (pid: 45743)
[2023-11-30 21:30:07 +0000] [45744] [ERROR] Exception in worker process
Traceback (most recent call last):
  File "/usr/local/lib/python3.8/dist-packages/gunicorn/arbiter.py", line 609, in spawn_worker
    worker.init_process()
  File "/usr/local/lib/python3.8/dist-packages/gunicorn/workers/base.py", line 134, in init_process
    self.load_wsgi()
  File "/usr/local/lib/python3.8/dist-packages/gunicorn/workers/base.py", line 146, in load_wsgi
    self.wsgi = self.app.wsgi()
  File "/usr/local/lib/python3.8/dist-packages/gunicorn/app/base.py", line 67, in wsgi
    self.callable = self.load()
  File "/usr/local/lib/python3.8/dist-packages/gunicorn/app/wsgiapp.py", line 58, in load
    return self.load_wsgiapp()
  File "/usr/local/lib/python3.8/dist-packages/gunicorn/app/wsgiapp.py", line 48, in load_wsgiapp
    return util.import_app(self.app_uri)
  File "/usr/local/lib/python3.8/dist-packages/gunicorn/util.py", line 371, in import_app
    mod = importlib.import_module(module)
  File "/usr/lib/python3.8/importlib/__init__.py", line 127, in import_module
    return _bootstrap._gcd_import(name[level:], package, level)
  File "<frozen importlib._bootstrap>", line 1014, in _gcd_import
  File "<frozen importlib._bootstrap>", line 991, in _find_and_load
  File "<frozen importlib._bootstrap>", line 975, in _find_and_load_unlocked
  File "<frozen importlib._bootstrap>", line 671, in _load_unlocked
  File "<frozen importlib._bootstrap_external>", line 848, in exec_module
  File "<frozen importlib._bootstrap>", line 219, in _call_with_frames_removed
  File "/home/ammo/public/app.py", line 36, in <module>
    execute_query('''
  File "/home/ammo/public/app.py", line 25, in execute_query
    with mysql.connector.connect(**db_config) as connection:
NameError: name 'db_config' is not defined
[2023-11-30 21:30:07 +0000] [45744] [INFO] Worker exiting (pid: 45744)
[2023-11-30 21:30:07 +0000] [45739] [ERROR] Worker (pid:45743) exited with code 3
[2023-11-30 21:30:07 +0000] [45739] [ERROR] Worker (pid:45744) exited with code 3
Traceback (most recent call last):
  File "/usr/local/lib/python3.8/dist-packages/gunicorn/arbiter.py", line 209, in run
    self.sleep()
  File "/usr/local/lib/python3.8/dist-packages/gunicorn/arbiter.py", line 360, in sleep
    ready = select.select([self.PIPE[0]], [], [], 1.0)
  File "/usr/local/lib/python3.8/dist-packages/gunicorn/arbiter.py", line 242, in handle_chld
    self.reap_workers()
  File "/usr/local/lib/python3.8/dist-packages/gunicorn/arbiter.py", line 530, in reap_workers
    raise HaltServer(reason, self.WORKER_BOOT_ERROR)
gunicorn.errors.HaltServer: <HaltServer 'Worker failed to boot.' 3>

During handling of the above exception, another exception occurred:

Traceback (most recent call last):
  File "/usr/local/bin/gunicorn", line 8, in <module>
    sys.exit(run())
  File "/usr/local/lib/python3.8/dist-packages/gunicorn/app/wsgiapp.py", line 67, in run
    WSGIApplication("%(prog)s [OPTIONS] [APP_MODULE]").run()
  File "/usr/local/lib/python3.8/dist-packages/gunicorn/app/base.py", line 236, in run
    super().run()
  File "/usr/local/lib/python3.8/dist-packages/gunicorn/app/base.py", line 72, in run
    Arbiter(self).run()
  File "/usr/local/lib/python3.8/dist-packages/gunicorn/arbiter.py", line 229, in run
    self.halt(reason=inst.reason, exit_status=inst.exit_status)
  File "/usr/local/lib/python3.8/dist-packages/gunicorn/arbiter.py", line 342, in halt
    self.stop()
  File "/usr/local/lib/python3.8/dist-packages/gunicorn/arbiter.py", line 396, in stop
    time.sleep(0.1)
  File "/usr/local/lib/python3.8/dist-packages/gunicorn/arbiter.py", line 242, in handle_chld
    self.reap_workers()
  File "/usr/local/lib/python3.8/dist-packages/gunicorn/arbiter.py", line 530, in reap_workers
    raise HaltServer(reason, self.WORKER_BOOT_ERROR)
gunicorn.errors.HaltServer: <HaltServer 'Worker failed to boot.' 3>
Error in sys.excepthook:
Traceback (most recent call last):
  File "/usr/lib/python3/dist-packages/apport_python_hook.py", line 62, in apport_excepthook
    if not enabled():
  File "/usr/lib/python3/dist-packages/apport_python_hook.py", line 28, in enabled
    return re.search(r'^\s*enabled\s*=\s*0\s*$', conf, re.M) is None
  File "/usr/lib/python3.8/re.py", line 201, in search
    return _compile(pattern, flags).search(string)
  File "/usr/lib/python3.8/re.py", line 304, in _compile
    p = sre_compile.compile(pattern, flags)
  File "/usr/lib/python3.8/sre_compile.py", line 764, in compile
    p = sre_parse.parse(p, flags)
  File "/usr/lib/python3.8/sre_parse.py", line 948, in parse
    p = _parse_sub(source, state, flags & SRE_FLAG_VERBOSE, 0)
  File "/usr/lib/python3.8/sre_parse.py", line 441, in _parse_sub
    start = source.tell()
  File "/usr/local/lib/python3.8/dist-packages/gunicorn/arbiter.py", line 242, in handle_chld
    self.reap_workers()
  File "/usr/local/lib/python3.8/dist-packages/gunicorn/arbiter.py", line 530, in reap_workers
    raise HaltServer(reason, self.WORKER_BOOT_ERROR)
gunicorn.errors.HaltServer: <HaltServer 'Worker failed to boot.' 3>

Original exception was:
Traceback (most recent call last):
  File "/usr/local/lib/python3.8/dist-packages/gunicorn/arbiter.py", line 209, in run
    self.sleep()
  File "/usr/local/lib/python3.8/dist-packages/gunicorn/arbiter.py", line 360, in sleep
    ready = select.select([self.PIPE[0]], [], [], 1.0)
  File "/usr/local/lib/python3.8/dist-packages/gunicorn/arbiter.py", line 242, in handle_chld
    self.reap_workers()
  File "/usr/local/lib/python3.8/dist-packages/gunicorn/arbiter.py", line 530, in reap_workers
    raise HaltServer(reason, self.WORKER_BOOT_ERROR)
gunicorn.errors.HaltServer: <HaltServer 'Worker failed to boot.' 3>

During handling of the above exception, another exception occurred:

Traceback (most recent call last):
  File "/usr/local/bin/gunicorn", line 8, in <module>
    sys.exit(run())
  File "/usr/local/lib/python3.8/dist-packages/gunicorn/app/wsgiapp.py", line 67, in run
    WSGIApplication("%(prog)s [OPTIONS] [APP_MODULE]").run()
  File "/usr/local/lib/python3.8/dist-packages/gunicorn/app/base.py", line 236, in run
    super().run()
  File "/usr/local/lib/python3.8/dist-packages/gunicorn/app/base.py", line 72, in run
    Arbiter(self).run()
  File "/usr/local/lib/python3.8/dist-packages/gunicorn/arbiter.py", line 229, in run
    self.halt(reason=inst.reason, exit_status=inst.exit_status)
  File "/usr/local/lib/python3.8/dist-packages/gunicorn/arbiter.py", line 342, in halt
    self.stop()
  File "/usr/local/lib/python3.8/dist-packages/gunicorn/arbiter.py", line 396, in stop
    time.sleep(0.1)
  File "/usr/local/lib/python3.8/dist-packages/gunicorn/arbiter.py", line 242, in handle_chld
    self.reap_workers()
  File "/usr/local/lib/python3.8/dist-packages/gunicorn/arbiter.py", line 530, in reap_workers
    raise HaltServer(reason, self.WORKER_BOOT_ERROR)
gunicorn.errors.HaltServer: <HaltServer 'Worker failed to boot.' 3>
[2023-11-30 21:30:58 +0000] [45753] [INFO] Starting gunicorn 21.2.0
[2023-11-30 21:30:58 +0000] [45753] [INFO] Listening at: http://127.0.0.1:5000 (45753)
[2023-11-30 21:30:58 +0000] [45753] [INFO] Using worker: sync
[2023-11-30 21:30:58 +0000] [45755] [INFO] Booting worker with pid: 45755
[2023-11-30 21:30:58 +0000] [45756] [INFO] Booting worker with pid: 45756
[2023-11-30 21:30:58 +0000] [45757] [INFO] Booting worker with pid: 45757
[2023-11-30 21:30:58 +0000] [45758] [INFO] Booting worker with pid: 45758
[2023-11-30 21:30:58 +0000] [45755] [ERROR] Exception in worker process
Traceback (most recent call last):
  File "/usr/local/lib/python3.8/dist-packages/gunicorn/arbiter.py", line 609, in spawn_worker
    worker.init_process()
  File "/usr/local/lib/python3.8/dist-packages/gunicorn/workers/base.py", line 134, in init_process
    self.load_wsgi()
  File "/usr/local/lib/python3.8/dist-packages/gunicorn/workers/base.py", line 146, in load_wsgi
    self.wsgi = self.app.wsgi()
  File "/usr/local/lib/python3.8/dist-packages/gunicorn/app/base.py", line 67, in wsgi
    self.callable = self.load()
  File "/usr/local/lib/python3.8/dist-packages/gunicorn/app/wsgiapp.py", line 58, in load
    return self.load_wsgiapp()
  File "/usr/local/lib/python3.8/dist-packages/gunicorn/app/wsgiapp.py", line 48, in load_wsgiapp
    return util.import_app(self.app_uri)
  File "/usr/local/lib/python3.8/dist-packages/gunicorn/util.py", line 371, in import_app
    mod = importlib.import_module(module)
  File "/usr/lib/python3.8/importlib/__init__.py", line 127, in import_module
    return _bootstrap._gcd_import(name[level:], package, level)
  File "<frozen importlib._bootstrap>", line 1014, in _gcd_import
  File "<frozen importlib._bootstrap>", line 991, in _find_and_load
  File "<frozen importlib._bootstrap>", line 975, in _find_and_load_unlocked
  File "<frozen importlib._bootstrap>", line 671, in _load_unlocked
  File "<frozen importlib._bootstrap_external>", line 848, in exec_module
  File "<frozen importlib._bootstrap>", line 219, in _call_with_frames_removed
  File "/home/ammo/public/app.py", line 36, in <module>
    execute_query('''
  File "/home/ammo/public/app.py", line 25, in execute_query
    with mysql.connector.connect(**db_config) as connection:
NameError: name 'db_config' is not defined
[2023-11-30 21:30:58 +0000] [45755] [INFO] Worker exiting (pid: 45755)
[2023-11-30 21:30:58 +0000] [45756] [ERROR] Exception in worker process
Traceback (most recent call last):
  File "/usr/local/lib/python3.8/dist-packages/gunicorn/arbiter.py", line 609, in spawn_worker
    worker.init_process()
  File "/usr/local/lib/python3.8/dist-packages/gunicorn/workers/base.py", line 134, in init_process
    self.load_wsgi()
  File "/usr/local/lib/python3.8/dist-packages/gunicorn/workers/base.py", line 146, in load_wsgi
    self.wsgi = self.app.wsgi()
  File "/usr/local/lib/python3.8/dist-packages/gunicorn/app/base.py", line 67, in wsgi
    self.callable = self.load()
  File "/usr/local/lib/python3.8/dist-packages/gunicorn/app/wsgiapp.py", line 58, in load
    return self.load_wsgiapp()
  File "/usr/local/lib/python3.8/dist-packages/gunicorn/app/wsgiapp.py", line 48, in load_wsgiapp
    return util.import_app(self.app_uri)
  File "/usr/local/lib/python3.8/dist-packages/gunicorn/util.py", line 371, in import_app
    mod = importlib.import_module(module)
  File "/usr/lib/python3.8/importlib/__init__.py", line 127, in import_module
    return _bootstrap._gcd_import(name[level:], package, level)
  File "<frozen importlib._bootstrap>", line 1014, in _gcd_import
  File "<frozen importlib._bootstrap>", line 991, in _find_and_load
  File "<frozen importlib._bootstrap>", line 975, in _find_and_load_unlocked
  File "<frozen importlib._bootstrap>", line 671, in _load_unlocked
  File "<frozen importlib._bootstrap_external>", line 848, in exec_module
  File "<frozen importlib._bootstrap>", line 219, in _call_with_frames_removed
  File "/home/ammo/public/app.py", line 36, in <module>
    execute_query('''
  File "/home/ammo/public/app.py", line 25, in execute_query
    with mysql.connector.connect(**db_config) as connection:
NameError: name 'db_config' is not defined
[2023-11-30 21:30:58 +0000] [45756] [INFO] Worker exiting (pid: 45756)
[2023-11-30 21:30:58 +0000] [45757] [ERROR] Exception in worker process
Traceback (most recent call last):
  File "/usr/local/lib/python3.8/dist-packages/gunicorn/arbiter.py", line 609, in spawn_worker
    worker.init_process()
  File "/usr/local/lib/python3.8/dist-packages/gunicorn/workers/base.py", line 134, in init_process
    self.load_wsgi()
  File "/usr/local/lib/python3.8/dist-packages/gunicorn/workers/base.py", line 146, in load_wsgi
    self.wsgi = self.app.wsgi()
  File "/usr/local/lib/python3.8/dist-packages/gunicorn/app/base.py", line 67, in wsgi
    self.callable = self.load()
  File "/usr/local/lib/python3.8/dist-packages/gunicorn/app/wsgiapp.py", line 58, in load
    return self.load_wsgiapp()
  File "/usr/local/lib/python3.8/dist-packages/gunicorn/app/wsgiapp.py", line 48, in load_wsgiapp
    return util.import_app(self.app_uri)
  File "/usr/local/lib/python3.8/dist-packages/gunicorn/util.py", line 371, in import_app
    mod = importlib.import_module(module)
  File "/usr/lib/python3.8/importlib/__init__.py", line 127, in import_module
    return _bootstrap._gcd_import(name[level:], package, level)
  File "<frozen importlib._bootstrap>", line 1014, in _gcd_import
  File "<frozen importlib._bootstrap>", line 991, in _find_and_load
  File "<frozen importlib._bootstrap>", line 975, in _find_and_load_unlocked
  File "<frozen importlib._bootstrap>", line 671, in _load_unlocked
  File "<frozen importlib._bootstrap_external>", line 848, in exec_module
  File "<frozen importlib._bootstrap>", line 219, in _call_with_frames_removed
  File "/home/ammo/public/app.py", line 36, in <module>
    execute_query('''
  File "/home/ammo/public/app.py", line 25, in execute_query
    with mysql.connector.connect(**db_config) as connection:
NameError: name 'db_config' is not defined
[2023-11-30 21:30:58 +0000] [45757] [INFO] Worker exiting (pid: 45757)
[2023-11-30 21:30:59 +0000] [45758] [ERROR] Exception in worker process
Traceback (most recent call last):
  File "/usr/local/lib/python3.8/dist-packages/gunicorn/arbiter.py", line 609, in spawn_worker
    worker.init_process()
  File "/usr/local/lib/python3.8/dist-packages/gunicorn/workers/base.py", line 134, in init_process
    self.load_wsgi()
  File "/usr/local/lib/python3.8/dist-packages/gunicorn/workers/base.py", line 146, in load_wsgi
    self.wsgi = self.app.wsgi()
  File "/usr/local/lib/python3.8/dist-packages/gunicorn/app/base.py", line 67, in wsgi
    self.callable = self.load()
  File "/usr/local/lib/python3.8/dist-packages/gunicorn/app/wsgiapp.py", line 58, in load
    return self.load_wsgiapp()
  File "/usr/local/lib/python3.8/dist-packages/gunicorn/app/wsgiapp.py", line 48, in load_wsgiapp
    return util.import_app(self.app_uri)
  File "/usr/local/lib/python3.8/dist-packages/gunicorn/util.py", line 371, in import_app
    mod = importlib.import_module(module)
  File "/usr/lib/python3.8/importlib/__init__.py", line 127, in import_module
    return _bootstrap._gcd_import(name[level:], package, level)
  File "<frozen importlib._bootstrap>", line 1014, in _gcd_import
  File "<frozen importlib._bootstrap>", line 991, in _find_and_load
  File "<frozen importlib._bootstrap>", line 975, in _find_and_load_unlocked
  File "<frozen importlib._bootstrap>", line 671, in _load_unlocked
  File "<frozen importlib._bootstrap_external>", line 848, in exec_module
  File "<frozen importlib._bootstrap>", line 219, in _call_with_frames_removed
  File "/home/ammo/public/app.py", line 36, in <module>
    execute_query('''
  File "/home/ammo/public/app.py", line 25, in execute_query
    with mysql.connector.connect(**db_config) as connection:
NameError: name 'db_config' is not defined
[2023-11-30 21:30:59 +0000] [45753] [ERROR] Worker (pid:45755) exited with code 3
[2023-11-30 21:30:59 +0000] [45758] [INFO] Worker exiting (pid: 45758)
[2023-11-30 21:30:59 +0000] [45753] [ERROR] Worker (pid:45757) was sent SIGTERM!
[2023-11-30 21:30:59 +0000] [45753] [ERROR] Worker (pid:45756) was sent SIGTERM!
[2023-11-30 21:30:59 +0000] [45753] [ERROR] Worker (pid:45758) exited with code 3
Traceback (most recent call last):
  File "/usr/local/lib/python3.8/dist-packages/gunicorn/arbiter.py", line 209, in run
    self.sleep()
  File "/usr/local/lib/python3.8/dist-packages/gunicorn/arbiter.py", line 360, in sleep
    ready = select.select([self.PIPE[0]], [], [], 1.0)
  File "/usr/local/lib/python3.8/dist-packages/gunicorn/arbiter.py", line 242, in handle_chld
    self.reap_workers()
  File "/usr/local/lib/python3.8/dist-packages/gunicorn/arbiter.py", line 530, in reap_workers
    raise HaltServer(reason, self.WORKER_BOOT_ERROR)
gunicorn.errors.HaltServer: <HaltServer 'Worker failed to boot.' 3>

During handling of the above exception, another exception occurred:

Traceback (most recent call last):
  File "/usr/local/bin/gunicorn", line 8, in <module>
    sys.exit(run())
  File "/usr/local/lib/python3.8/dist-packages/gunicorn/app/wsgiapp.py", line 67, in run
    WSGIApplication("%(prog)s [OPTIONS] [APP_MODULE]").run()
  File "/usr/local/lib/python3.8/dist-packages/gunicorn/app/base.py", line 236, in run
    super().run()
  File "/usr/local/lib/python3.8/dist-packages/gunicorn/app/base.py", line 72, in run
    Arbiter(self).run()
  File "/usr/local/lib/python3.8/dist-packages/gunicorn/arbiter.py", line 229, in run
    self.halt(reason=inst.reason, exit_status=inst.exit_status)
  File "/usr/local/lib/python3.8/dist-packages/gunicorn/arbiter.py", line 342, in halt
    self.stop()
  File "/usr/local/lib/python3.8/dist-packages/gunicorn/arbiter.py", line 396, in stop
    time.sleep(0.1)
  File "/usr/local/lib/python3.8/dist-packages/gunicorn/arbiter.py", line 242, in handle_chld
    self.reap_workers()
  File "/usr/local/lib/python3.8/dist-packages/gunicorn/arbiter.py", line 530, in reap_workers
    raise HaltServer(reason, self.WORKER_BOOT_ERROR)
gunicorn.errors.HaltServer: <HaltServer 'Worker failed to boot.' 3>
[2023-11-30 21:33:01 +0000] [45765] [INFO] Starting gunicorn 21.2.0
[2023-11-30 21:33:01 +0000] [45765] [INFO] Listening at: http://127.0.0.1:5000 (45765)
[2023-11-30 21:33:01 +0000] [45765] [INFO] Using worker: sync
[2023-11-30 21:33:01 +0000] [45767] [INFO] Booting worker with pid: 45767
[2023-11-30 21:33:01 +0000] [45768] [INFO] Booting worker with pid: 45768
[2023-11-30 21:33:01 +0000] [45769] [INFO] Booting worker with pid: 45769
[2023-11-30 21:33:01 +0000] [45770] [INFO] Booting worker with pid: 45770
[2023-11-30 21:33:02 +0000] [45767] [ERROR] Exception in worker process
Traceback (most recent call last):
  File "/usr/local/lib/python3.8/dist-packages/gunicorn/arbiter.py", line 609, in spawn_worker
    worker.init_process()
  File "/usr/local/lib/python3.8/dist-packages/gunicorn/workers/base.py", line 134, in init_process
    self.load_wsgi()
  File "/usr/local/lib/python3.8/dist-packages/gunicorn/workers/base.py", line 146, in load_wsgi
    self.wsgi = self.app.wsgi()
  File "/usr/local/lib/python3.8/dist-packages/gunicorn/app/base.py", line 67, in wsgi
    self.callable = self.load()
  File "/usr/local/lib/python3.8/dist-packages/gunicorn/app/wsgiapp.py", line 58, in load
    return self.load_wsgiapp()
  File "/usr/local/lib/python3.8/dist-packages/gunicorn/app/wsgiapp.py", line 48, in load_wsgiapp
    return util.import_app(self.app_uri)
  File "/usr/local/lib/python3.8/dist-packages/gunicorn/util.py", line 371, in import_app
    mod = importlib.import_module(module)
  File "/usr/lib/python3.8/importlib/__init__.py", line 127, in import_module
    return _bootstrap._gcd_import(name[level:], package, level)
  File "<frozen importlib._bootstrap>", line 1014, in _gcd_import
  File "<frozen importlib._bootstrap>", line 991, in _find_and_load
  File "<frozen importlib._bootstrap>", line 975, in _find_and_load_unlocked
  File "<frozen importlib._bootstrap>", line 671, in _load_unlocked
  File "<frozen importlib._bootstrap_external>", line 848, in exec_module
  File "<frozen importlib._bootstrap>", line 219, in _call_with_frames_removed
  File "/home/ammo/public/app.py", line 36, in <module>
    execute_query('''
  File "/home/ammo/public/app.py", line 25, in execute_query
    with mysql.connector.connect(**db_config) as connection:
NameError: name 'db_config' is not defined
[2023-11-30 21:33:02 +0000] [45767] [INFO] Worker exiting (pid: 45767)
[2023-11-30 21:33:02 +0000] [45765] [ERROR] Worker (pid:45767) exited with code 3
[2023-11-30 21:33:02 +0000] [45768] [ERROR] Exception in worker process
Traceback (most recent call last):
  File "/usr/local/lib/python3.8/dist-packages/gunicorn/arbiter.py", line 609, in spawn_worker
    worker.init_process()
  File "/usr/local/lib/python3.8/dist-packages/gunicorn/workers/base.py", line 134, in init_process
    self.load_wsgi()
  File "/usr/local/lib/python3.8/dist-packages/gunicorn/workers/base.py", line 146, in load_wsgi
    self.wsgi = self.app.wsgi()
  File "/usr/local/lib/python3.8/dist-packages/gunicorn/app/base.py", line 67, in wsgi
    self.callable = self.load()
  File "/usr/local/lib/python3.8/dist-packages/gunicorn/app/wsgiapp.py", line 58, in load
    return self.load_wsgiapp()
  File "/usr/local/lib/python3.8/dist-packages/gunicorn/app/wsgiapp.py", line 48, in load_wsgiapp
    return util.import_app(self.app_uri)
  File "/usr/local/lib/python3.8/dist-packages/gunicorn/util.py", line 371, in import_app
    mod = importlib.import_module(module)
  File "/usr/lib/python3.8/importlib/__init__.py", line 127, in import_module
    return _bootstrap._gcd_import(name[level:], package, level)
  File "<frozen importlib._bootstrap>", line 1014, in _gcd_import
  File "<frozen importlib._bootstrap>", line 991, in _find_and_load
  File "<frozen importlib._bootstrap>", line 975, in _find_and_load_unlocked
  File "<frozen importlib._bootstrap>", line 671, in _load_unlocked
  File "<frozen importlib._bootstrap_external>", line 848, in exec_module
  File "<frozen importlib._bootstrap>", line 219, in _call_with_frames_removed
  File "/home/ammo/public/app.py", line 36, in <module>
    execute_query('''
  File "/home/ammo/public/app.py", line 25, in execute_query
    with mysql.connector.connect(**db_config) as connection:
NameError: name 'db_config' is not defined
[2023-11-30 21:33:02 +0000] [45768] [INFO] Worker exiting (pid: 45768)
[2023-11-30 21:33:02 +0000] [45769] [ERROR] Exception in worker process
Traceback (most recent call last):
  File "/usr/local/lib/python3.8/dist-packages/gunicorn/arbiter.py", line 609, in spawn_worker
    worker.init_process()
  File "/usr/local/lib/python3.8/dist-packages/gunicorn/workers/base.py", line 134, in init_process
    self.load_wsgi()
  File "/usr/local/lib/python3.8/dist-packages/gunicorn/workers/base.py", line 146, in load_wsgi
    self.wsgi = self.app.wsgi()
  File "/usr/local/lib/python3.8/dist-packages/gunicorn/app/base.py", line 67, in wsgi
    self.callable = self.load()
  File "/usr/local/lib/python3.8/dist-packages/gunicorn/app/wsgiapp.py", line 58, in load
    return self.load_wsgiapp()
  File "/usr/local/lib/python3.8/dist-packages/gunicorn/app/wsgiapp.py", line 48, in load_wsgiapp
    return util.import_app(self.app_uri)
  File "/usr/local/lib/python3.8/dist-packages/gunicorn/util.py", line 371, in import_app
    mod = importlib.import_module(module)
  File "/usr/lib/python3.8/importlib/__init__.py", line 127, in import_module
    return _bootstrap._gcd_import(name[level:], package, level)
  File "<frozen importlib._bootstrap>", line 1014, in _gcd_import
  File "<frozen importlib._bootstrap>", line 991, in _find_and_load
  File "<frozen importlib._bootstrap>", line 975, in _find_and_load_unlocked
  File "<frozen importlib._bootstrap>", line 671, in _load_unlocked
  File "<frozen importlib._bootstrap_external>", line 848, in exec_module
  File "<frozen importlib._bootstrap>", line 219, in _call_with_frames_removed
  File "/home/ammo/public/app.py", line 36, in <module>
    execute_query('''
  File "/home/ammo/public/app.py", line 25, in execute_query
    with mysql.connector.connect(**db_config) as connection:
NameError: name 'db_config' is not defined
[2023-11-30 21:33:02 +0000] [45769] [INFO] Worker exiting (pid: 45769)
[2023-11-30 21:33:02 +0000] [45770] [ERROR] Exception in worker process
Traceback (most recent call last):
  File "/usr/local/lib/python3.8/dist-packages/gunicorn/arbiter.py", line 609, in spawn_worker
    worker.init_process()
  File "/usr/local/lib/python3.8/dist-packages/gunicorn/workers/base.py", line 134, in init_process
    self.load_wsgi()
  File "/usr/local/lib/python3.8/dist-packages/gunicorn/workers/base.py", line 146, in load_wsgi
    self.wsgi = self.app.wsgi()
  File "/usr/local/lib/python3.8/dist-packages/gunicorn/app/base.py", line 67, in wsgi
    self.callable = self.load()
  File "/usr/local/lib/python3.8/dist-packages/gunicorn/app/wsgiapp.py", line 58, in load
    return self.load_wsgiapp()
  File "/usr/local/lib/python3.8/dist-packages/gunicorn/app/wsgiapp.py", line 48, in load_wsgiapp
    return util.import_app(self.app_uri)
  File "/usr/local/lib/python3.8/dist-packages/gunicorn/util.py", line 371, in import_app
    mod = importlib.import_module(module)
  File "/usr/lib/python3.8/importlib/__init__.py", line 127, in import_module
    return _bootstrap._gcd_import(name[level:], package, level)
  File "<frozen importlib._bootstrap>", line 1014, in _gcd_import
  File "<frozen importlib._bootstrap>", line 991, in _find_and_load
  File "<frozen importlib._bootstrap>", line 975, in _find_and_load_unlocked
  File "<frozen importlib._bootstrap>", line 671, in _load_unlocked
  File "<frozen importlib._bootstrap_external>", line 848, in exec_module
  File "<frozen importlib._bootstrap>", line 219, in _call_with_frames_removed
  File "/home/ammo/public/app.py", line 36, in <module>
    execute_query('''
  File "/home/ammo/public/app.py", line 25, in execute_query
    with mysql.connector.connect(**db_config) as connection:
NameError: name 'db_config' is not defined
[2023-11-30 21:33:02 +0000] [45770] [INFO] Worker exiting (pid: 45770)
[2023-11-30 21:33:02 +0000] [45765] [ERROR] Worker (pid:45768) exited with code 3
[2023-11-30 21:33:02 +0000] [45765] [ERROR] Worker (pid:45769) exited with code 3
Traceback (most recent call last):
  File "/usr/local/lib/python3.8/dist-packages/gunicorn/arbiter.py", line 209, in run
    self.sleep()
  File "/usr/local/lib/python3.8/dist-packages/gunicorn/arbiter.py", line 360, in sleep
    ready = select.select([self.PIPE[0]], [], [], 1.0)
  File "/usr/local/lib/python3.8/dist-packages/gunicorn/arbiter.py", line 242, in handle_chld
    self.reap_workers()
  File "/usr/local/lib/python3.8/dist-packages/gunicorn/arbiter.py", line 530, in reap_workers
    raise HaltServer(reason, self.WORKER_BOOT_ERROR)
gunicorn.errors.HaltServer: <HaltServer 'Worker failed to boot.' 3>

During handling of the above exception, another exception occurred:

Traceback (most recent call last):
  File "/usr/local/bin/gunicorn", line 8, in <module>
    sys.exit(run())
  File "/usr/local/lib/python3.8/dist-packages/gunicorn/app/wsgiapp.py", line 67, in run
    WSGIApplication("%(prog)s [OPTIONS] [APP_MODULE]").run()
  File "/usr/local/lib/python3.8/dist-packages/gunicorn/app/base.py", line 236, in run
    super().run()
  File "/usr/local/lib/python3.8/dist-packages/gunicorn/app/base.py", line 72, in run
    Arbiter(self).run()
  File "/usr/local/lib/python3.8/dist-packages/gunicorn/arbiter.py", line 229, in run
    self.halt(reason=inst.reason, exit_status=inst.exit_status)
  File "/usr/local/lib/python3.8/dist-packages/gunicorn/arbiter.py", line 342, in halt
    self.stop()
  File "/usr/local/lib/python3.8/dist-packages/gunicorn/arbiter.py", line 396, in stop
    time.sleep(0.1)
  File "/usr/local/lib/python3.8/dist-packages/gunicorn/arbiter.py", line 242, in handle_chld
    self.reap_workers()
  File "/usr/local/lib/python3.8/dist-packages/gunicorn/arbiter.py", line 530, in reap_workers
    raise HaltServer(reason, self.WORKER_BOOT_ERROR)
gunicorn.errors.HaltServer: <HaltServer 'Worker failed to boot.' 3>
Error in sys.excepthook:
Traceback (most recent call last):
  File "/usr/lib/python3/dist-packages/apport_python_hook.py", line 72, in apport_excepthook
    from apport.fileutils import likely_packaged, get_recent_crashes
  File "/usr/lib/python3/dist-packages/apport/__init__.py", line 5, in <module>
    from apport.report import Report
  File "/usr/lib/python3/dist-packages/apport/report.py", line 30, in <module>
    import problem_report
  File "/usr/lib/python3/dist-packages/problem_report.py", line 17, in <module>
    from email.mime.multipart import MIMEMultipart
  File "/usr/lib/python3.8/email/mime/multipart.py", line 9, in <module>
    from email.mime.base import MIMEBase
  File "/usr/lib/python3.8/email/mime/base.py", line 9, in <module>
    import email.policy
  File "<frozen importlib._bootstrap>", line 991, in _find_and_load
  File "<frozen importlib._bootstrap>", line 971, in _find_and_load_unlocked
  File "<frozen importlib._bootstrap>", line 914, in _find_spec
  File "<frozen importlib._bootstrap_external>", line 1407, in find_spec
  File "<frozen importlib._bootstrap_external>", line 1379, in _get_spec
  File "<frozen importlib._bootstrap_external>", line 1534, in find_spec
  File "<frozen importlib._bootstrap_external>", line 123, in _path_join
  File "/usr/local/lib/python3.8/dist-packages/gunicorn/arbiter.py", line 242, in handle_chld
    self.reap_workers()
  File "/usr/local/lib/python3.8/dist-packages/gunicorn/arbiter.py", line 530, in reap_workers
    raise HaltServer(reason, self.WORKER_BOOT_ERROR)
gunicorn.errors.HaltServer: <HaltServer 'Worker failed to boot.' 3>

Original exception was:
Traceback (most recent call last):
  File "/usr/local/lib/python3.8/dist-packages/gunicorn/arbiter.py", line 209, in run
    self.sleep()
  File "/usr/local/lib/python3.8/dist-packages/gunicorn/arbiter.py", line 360, in sleep
    ready = select.select([self.PIPE[0]], [], [], 1.0)
  File "/usr/local/lib/python3.8/dist-packages/gunicorn/arbiter.py", line 242, in handle_chld
    self.reap_workers()
  File "/usr/local/lib/python3.8/dist-packages/gunicorn/arbiter.py", line 530, in reap_workers
    raise HaltServer(reason, self.WORKER_BOOT_ERROR)
gunicorn.errors.HaltServer: <HaltServer 'Worker failed to boot.' 3>

During handling of the above exception, another exception occurred:

Traceback (most recent call last):
  File "/usr/local/bin/gunicorn", line 8, in <module>
    sys.exit(run())
  File "/usr/local/lib/python3.8/dist-packages/gunicorn/app/wsgiapp.py", line 67, in run
    WSGIApplication("%(prog)s [OPTIONS] [APP_MODULE]").run()
  File "/usr/local/lib/python3.8/dist-packages/gunicorn/app/base.py", line 236, in run
    super().run()
  File "/usr/local/lib/python3.8/dist-packages/gunicorn/app/base.py", line 72, in run
    Arbiter(self).run()
  File "/usr/local/lib/python3.8/dist-packages/gunicorn/arbiter.py", line 229, in run
    self.halt(reason=inst.reason, exit_status=inst.exit_status)
  File "/usr/local/lib/python3.8/dist-packages/gunicorn/arbiter.py", line 342, in halt
    self.stop()
  File "/usr/local/lib/python3.8/dist-packages/gunicorn/arbiter.py", line 396, in stop
    time.sleep(0.1)
  File "/usr/local/lib/python3.8/dist-packages/gunicorn/arbiter.py", line 242, in handle_chld
    self.reap_workers()
  File "/usr/local/lib/python3.8/dist-packages/gunicorn/arbiter.py", line 530, in reap_workers
    raise HaltServer(reason, self.WORKER_BOOT_ERROR)
gunicorn.errors.HaltServer: <HaltServer 'Worker failed to boot.' 3>
[2023-11-30 21:34:50 +0000] [45816] [INFO] Starting gunicorn 21.2.0
[2023-11-30 21:34:50 +0000] [45816] [INFO] Listening at: http://127.0.0.1:5000 (45816)
[2023-11-30 21:34:50 +0000] [45816] [INFO] Using worker: sync
[2023-11-30 21:34:50 +0000] [45818] [INFO] Booting worker with pid: 45818
[2023-11-30 21:34:50 +0000] [45819] [INFO] Booting worker with pid: 45819
[2023-11-30 21:34:50 +0000] [45820] [INFO] Booting worker with pid: 45820
[2023-11-30 21:34:50 +0000] [45821] [INFO] Booting worker with pid: 45821
[2023-11-30 21:34:50 +0000] [45818] [ERROR] Exception in worker process
Traceback (most recent call last):
  File "/usr/local/lib/python3.8/dist-packages/gunicorn/arbiter.py", line 609, in spawn_worker
    worker.init_process()
  File "/usr/local/lib/python3.8/dist-packages/gunicorn/workers/base.py", line 134, in init_process
    self.load_wsgi()
  File "/usr/local/lib/python3.8/dist-packages/gunicorn/workers/base.py", line 146, in load_wsgi
    self.wsgi = self.app.wsgi()
  File "/usr/local/lib/python3.8/dist-packages/gunicorn/app/base.py", line 67, in wsgi
    self.callable = self.load()
  File "/usr/local/lib/python3.8/dist-packages/gunicorn/app/wsgiapp.py", line 58, in load
    return self.load_wsgiapp()
  File "/usr/local/lib/python3.8/dist-packages/gunicorn/app/wsgiapp.py", line 48, in load_wsgiapp
    return util.import_app(self.app_uri)
  File "/usr/local/lib/python3.8/dist-packages/gunicorn/util.py", line 371, in import_app
    mod = importlib.import_module(module)
  File "/usr/lib/python3.8/importlib/__init__.py", line 127, in import_module
    return _bootstrap._gcd_import(name[level:], package, level)
  File "<frozen importlib._bootstrap>", line 1014, in _gcd_import
  File "<frozen importlib._bootstrap>", line 991, in _find_and_load
  File "<frozen importlib._bootstrap>", line 975, in _find_and_load_unlocked
  File "<frozen importlib._bootstrap>", line 671, in _load_unlocked
  File "<frozen importlib._bootstrap_external>", line 848, in exec_module
  File "<frozen importlib._bootstrap>", line 219, in _call_with_frames_removed
  File "/home/ammo/public/app.py", line 36, in <module>
    execute_query('''
  File "/home/ammo/public/app.py", line 25, in execute_query
    with mysql.connector.connect(**db_config) as connection:
NameError: name 'db_config' is not defined
[2023-11-30 21:34:50 +0000] [45818] [INFO] Worker exiting (pid: 45818)
[2023-11-30 21:34:50 +0000] [45819] [ERROR] Exception in worker process
Traceback (most recent call last):
  File "/usr/local/lib/python3.8/dist-packages/gunicorn/arbiter.py", line 609, in spawn_worker
    worker.init_process()
  File "/usr/local/lib/python3.8/dist-packages/gunicorn/workers/base.py", line 134, in init_process
    self.load_wsgi()
  File "/usr/local/lib/python3.8/dist-packages/gunicorn/workers/base.py", line 146, in load_wsgi
    self.wsgi = self.app.wsgi()
  File "/usr/local/lib/python3.8/dist-packages/gunicorn/app/base.py", line 67, in wsgi
    self.callable = self.load()
  File "/usr/local/lib/python3.8/dist-packages/gunicorn/app/wsgiapp.py", line 58, in load
    return self.load_wsgiapp()
  File "/usr/local/lib/python3.8/dist-packages/gunicorn/app/wsgiapp.py", line 48, in load_wsgiapp
    return util.import_app(self.app_uri)
  File "/usr/local/lib/python3.8/dist-packages/gunicorn/util.py", line 371, in import_app
    mod = importlib.import_module(module)
  File "/usr/lib/python3.8/importlib/__init__.py", line 127, in import_module
    return _bootstrap._gcd_import(name[level:], package, level)
  File "<frozen importlib._bootstrap>", line 1014, in _gcd_import
  File "<frozen importlib._bootstrap>", line 991, in _find_and_load
  File "<frozen importlib._bootstrap>", line 975, in _find_and_load_unlocked
  File "<frozen importlib._bootstrap>", line 671, in _load_unlocked
  File "<frozen importlib._bootstrap_external>", line 848, in exec_module
  File "<frozen importlib._bootstrap>", line 219, in _call_with_frames_removed
  File "/home/ammo/public/app.py", line 36, in <module>
    execute_query('''
  File "/home/ammo/public/app.py", line 25, in execute_query
    with mysql.connector.connect(**db_config) as connection:
NameError: name 'db_config' is not defined
[2023-11-30 21:34:50 +0000] [45819] [INFO] Worker exiting (pid: 45819)
[2023-11-30 21:34:51 +0000] [45820] [ERROR] Exception in worker process
Traceback (most recent call last):
  File "/usr/local/lib/python3.8/dist-packages/gunicorn/arbiter.py", line 609, in spawn_worker
    worker.init_process()
  File "/usr/local/lib/python3.8/dist-packages/gunicorn/workers/base.py", line 134, in init_process
    self.load_wsgi()
  File "/usr/local/lib/python3.8/dist-packages/gunicorn/workers/base.py", line 146, in load_wsgi
    self.wsgi = self.app.wsgi()
  File "/usr/local/lib/python3.8/dist-packages/gunicorn/app/base.py", line 67, in wsgi
    self.callable = self.load()
  File "/usr/local/lib/python3.8/dist-packages/gunicorn/app/wsgiapp.py", line 58, in load
    return self.load_wsgiapp()
  File "/usr/local/lib/python3.8/dist-packages/gunicorn/app/wsgiapp.py", line 48, in load_wsgiapp
    return util.import_app(self.app_uri)
  File "/usr/local/lib/python3.8/dist-packages/gunicorn/util.py", line 371, in import_app
    mod = importlib.import_module(module)
  File "/usr/lib/python3.8/importlib/__init__.py", line 127, in import_module
    return _bootstrap._gcd_import(name[level:], package, level)
  File "<frozen importlib._bootstrap>", line 1014, in _gcd_import
  File "<frozen importlib._bootstrap>", line 991, in _find_and_load
  File "<frozen importlib._bootstrap>", line 975, in _find_and_load_unlocked
  File "<frozen importlib._bootstrap>", line 671, in _load_unlocked
  File "<frozen importlib._bootstrap_external>", line 848, in exec_module
  File "<frozen importlib._bootstrap>", line 219, in _call_with_frames_removed
  File "/home/ammo/public/app.py", line 36, in <module>
    execute_query('''
  File "/home/ammo/public/app.py", line 25, in execute_query
    with mysql.connector.connect(**db_config) as connection:
NameError: name 'db_config' is not defined
[2023-11-30 21:34:51 +0000] [45820] [INFO] Worker exiting (pid: 45820)
[2023-11-30 21:34:51 +0000] [45816] [ERROR] Worker (pid:45818) exited with code 3
[2023-11-30 21:34:51 +0000] [45816] [ERROR] Worker (pid:45820) was sent SIGTERM!
[2023-11-30 21:34:51 +0000] [45816] [ERROR] Worker (pid:45819) was sent SIGTERM!
[2023-11-30 21:34:51 +0000] [45821] [ERROR] Exception in worker process
Traceback (most recent call last):
  File "/usr/local/lib/python3.8/dist-packages/gunicorn/arbiter.py", line 609, in spawn_worker
    worker.init_process()
  File "/usr/local/lib/python3.8/dist-packages/gunicorn/workers/base.py", line 134, in init_process
    self.load_wsgi()
  File "/usr/local/lib/python3.8/dist-packages/gunicorn/workers/base.py", line 146, in load_wsgi
    self.wsgi = self.app.wsgi()
  File "/usr/local/lib/python3.8/dist-packages/gunicorn/app/base.py", line 67, in wsgi
    self.callable = self.load()
  File "/usr/local/lib/python3.8/dist-packages/gunicorn/app/wsgiapp.py", line 58, in load
    return self.load_wsgiapp()
  File "/usr/local/lib/python3.8/dist-packages/gunicorn/app/wsgiapp.py", line 48, in load_wsgiapp
    return util.import_app(self.app_uri)
  File "/usr/local/lib/python3.8/dist-packages/gunicorn/util.py", line 371, in import_app
    mod = importlib.import_module(module)
  File "/usr/lib/python3.8/importlib/__init__.py", line 127, in import_module
    return _bootstrap._gcd_import(name[level:], package, level)
  File "<frozen importlib._bootstrap>", line 1014, in _gcd_import
  File "<frozen importlib._bootstrap>", line 991, in _find_and_load
  File "<frozen importlib._bootstrap>", line 975, in _find_and_load_unlocked
  File "<frozen importlib._bootstrap>", line 671, in _load_unlocked
  File "<frozen importlib._bootstrap_external>", line 848, in exec_module
  File "<frozen importlib._bootstrap>", line 219, in _call_with_frames_removed
  File "/home/ammo/public/app.py", line 36, in <module>
    execute_query('''
  File "/home/ammo/public/app.py", line 25, in execute_query
    with mysql.connector.connect(**db_config) as connection:
NameError: name 'db_config' is not defined
[2023-11-30 21:34:51 +0000] [45821] [INFO] Worker exiting (pid: 45821)
[2023-11-30 21:34:51 +0000] [45816] [ERROR] Worker (pid:45821) exited with code 3
Traceback (most recent call last):
  File "/usr/local/lib/python3.8/dist-packages/gunicorn/arbiter.py", line 209, in run
    self.sleep()
  File "/usr/local/lib/python3.8/dist-packages/gunicorn/arbiter.py", line 360, in sleep
    ready = select.select([self.PIPE[0]], [], [], 1.0)
  File "/usr/local/lib/python3.8/dist-packages/gunicorn/arbiter.py", line 242, in handle_chld
    self.reap_workers()
  File "/usr/local/lib/python3.8/dist-packages/gunicorn/arbiter.py", line 530, in reap_workers
    raise HaltServer(reason, self.WORKER_BOOT_ERROR)
gunicorn.errors.HaltServer: <HaltServer 'Worker failed to boot.' 3>

During handling of the above exception, another exception occurred:

Traceback (most recent call last):
  File "/usr/local/bin/gunicorn", line 8, in <module>
    sys.exit(run())
  File "/usr/local/lib/python3.8/dist-packages/gunicorn/app/wsgiapp.py", line 67, in run
    WSGIApplication("%(prog)s [OPTIONS] [APP_MODULE]").run()
  File "/usr/local/lib/python3.8/dist-packages/gunicorn/app/base.py", line 236, in run
    super().run()
  File "/usr/local/lib/python3.8/dist-packages/gunicorn/app/base.py", line 72, in run
    Arbiter(self).run()
  File "/usr/local/lib/python3.8/dist-packages/gunicorn/arbiter.py", line 229, in run
    self.halt(reason=inst.reason, exit_status=inst.exit_status)
  File "/usr/local/lib/python3.8/dist-packages/gunicorn/arbiter.py", line 342, in halt
    self.stop()
  File "/usr/local/lib/python3.8/dist-packages/gunicorn/arbiter.py", line 396, in stop
    time.sleep(0.1)
  File "/usr/local/lib/python3.8/dist-packages/gunicorn/arbiter.py", line 242, in handle_chld
    self.reap_workers()
  File "/usr/local/lib/python3.8/dist-packages/gunicorn/arbiter.py", line 530, in reap_workers
    raise HaltServer(reason, self.WORKER_BOOT_ERROR)
gunicorn.errors.HaltServer: <HaltServer 'Worker failed to boot.' 3>
[2023-11-30 21:54:46 +0000] [45935] [INFO] Starting gunicorn 21.2.0
[2023-11-30 21:54:46 +0000] [45935] [INFO] Listening at: http://127.0.0.1:5000 (45935)
[2023-11-30 21:54:46 +0000] [45935] [INFO] Using worker: sync
[2023-11-30 21:54:46 +0000] [45937] [INFO] Booting worker with pid: 45937
[2023-11-30 21:54:47 +0000] [45938] [INFO] Booting worker with pid: 45938
[2023-11-30 21:54:47 +0000] [45939] [INFO] Booting worker with pid: 45939
[2023-11-30 21:54:47 +0000] [45940] [INFO] Booting worker with pid: 45940
[2023-11-30 21:59:15,479] ERROR in app: Exception on /register [POST]
Traceback (most recent call last):
  File "/home/ammo/public/app.py", line 30, in execute_query
    connection.commit()
  File "/usr/local/lib/python3.8/dist-packages/mysql/connector/connection.py", line 1263, in commit
    self._execute_query("COMMIT")
  File "/usr/local/lib/python3.8/dist-packages/mysql/connector/connection.py", line 1281, in _execute_query
    self.handle_unread_result()
  File "/usr/local/lib/python3.8/dist-packages/mysql/connector/connection.py", line 1523, in handle_unread_result
    raise InternalError("Unread result found")
mysql.connector.errors.InternalError: Unread result found

During handling of the above exception, another exception occurred:

Traceback (most recent call last):
  File "/usr/local/lib/python3.8/dist-packages/flask/app.py", line 1455, in wsgi_app
    response = self.full_dispatch_request()
  File "/usr/local/lib/python3.8/dist-packages/flask/app.py", line 869, in full_dispatch_request
    rv = self.handle_user_exception(e)
  File "/usr/local/lib/python3.8/dist-packages/flask/app.py", line 867, in full_dispatch_request
    rv = self.dispatch_request()
  File "/usr/local/lib/python3.8/dist-packages/flask/app.py", line 852, in dispatch_request
    return self.ensure_sync(self.view_functions[rule.endpoint])(**view_args)
  File "/home/ammo/public/app.py", line 74, in register
    existing_user = execute_query('SELECT * FROM users WHERE username=%s', (username,), fetchone=True)
  File "/home/ammo/public/app.py", line 35, in execute_query
    return None
  File "/usr/local/lib/python3.8/dist-packages/mysql/connector/abstracts.py", line 1621, in __exit__
    self.close()
  File "/usr/local/lib/python3.8/dist-packages/mysql/connector/cursor.py", line 429, in close
    self._connection.handle_unread_result()
  File "/usr/local/lib/python3.8/dist-packages/mysql/connector/connection.py", line 1523, in handle_unread_result
    raise InternalError("Unread result found")
mysql.connector.errors.InternalError: Unread result found
[2023-11-30 22:21:18 +0000] [46080] [INFO] Starting gunicorn 21.2.0
[2023-11-30 22:21:18 +0000] [46080] [INFO] Listening at: http://127.0.0.1:5000 (46080)
[2023-11-30 22:21:18 +0000] [46080] [INFO] Using worker: sync
[2023-11-30 22:21:18 +0000] [46082] [INFO] Booting worker with pid: 46082
[2023-11-30 22:21:18 +0000] [46083] [INFO] Booting worker with pid: 46083
[2023-11-30 22:21:18 +0000] [46084] [INFO] Booting worker with pid: 46084
[2023-11-30 22:21:18 +0000] [46085] [INFO] Booting worker with pid: 46085
[2023-11-30 22:21:53,432] ERROR in app: Exception on /login [POST]
Traceback (most recent call last):
  File "/home/ammo/public/app.py", line 30, in execute_query
    connection.commit()
  File "/usr/local/lib/python3.8/dist-packages/mysql/connector/connection.py", line 1263, in commit
    self._execute_query("COMMIT")
  File "/usr/local/lib/python3.8/dist-packages/mysql/connector/connection.py", line 1281, in _execute_query
    self.handle_unread_result()
  File "/usr/local/lib/python3.8/dist-packages/mysql/connector/connection.py", line 1523, in handle_unread_result
    raise InternalError("Unread result found")
mysql.connector.errors.InternalError: Unread result found

During handling of the above exception, another exception occurred:

Traceback (most recent call last):
  File "/usr/local/lib/python3.8/dist-packages/flask/app.py", line 1455, in wsgi_app
    response = self.full_dispatch_request()
  File "/usr/local/lib/python3.8/dist-packages/flask/app.py", line 869, in full_dispatch_request
    rv = self.handle_user_exception(e)
  File "/usr/local/lib/python3.8/dist-packages/flask/app.py", line 867, in full_dispatch_request
    rv = self.dispatch_request()
  File "/usr/local/lib/python3.8/dist-packages/flask/app.py", line 852, in dispatch_request
    return self.ensure_sync(self.view_functions[rule.endpoint])(**view_args)
  File "/home/ammo/public/app.py", line 57, in login
    user = execute_query('SELECT * FROM users WHERE username=%s', (username,), fetchone=True)
  File "/home/ammo/public/app.py", line 35, in execute_query
    return None
  File "/usr/local/lib/python3.8/dist-packages/mysql/connector/abstracts.py", line 1621, in __exit__
    self.close()
  File "/usr/local/lib/python3.8/dist-packages/mysql/connector/cursor.py", line 429, in close
    self._connection.handle_unread_result()
  File "/usr/local/lib/python3.8/dist-packages/mysql/connector/connection.py", line 1523, in handle_unread_result
    raise InternalError("Unread result found")
mysql.connector.errors.InternalError: Unread result found
[2023-11-30 22:22:04,785] ERROR in app: Exception on /register [POST]
Traceback (most recent call last):
  File "/home/ammo/public/app.py", line 30, in execute_query
    connection.commit()
  File "/usr/local/lib/python3.8/dist-packages/mysql/connector/connection.py", line 1263, in commit
    self._execute_query("COMMIT")
  File "/usr/local/lib/python3.8/dist-packages/mysql/connector/connection.py", line 1281, in _execute_query
    self.handle_unread_result()
  File "/usr/local/lib/python3.8/dist-packages/mysql/connector/connection.py", line 1523, in handle_unread_result
    raise InternalError("Unread result found")
mysql.connector.errors.InternalError: Unread result found

During handling of the above exception, another exception occurred:

Traceback (most recent call last):
  File "/usr/local/lib/python3.8/dist-packages/flask/app.py", line 1455, in wsgi_app
    response = self.full_dispatch_request()
  File "/usr/local/lib/python3.8/dist-packages/flask/app.py", line 869, in full_dispatch_request
    rv = self.handle_user_exception(e)
  File "/usr/local/lib/python3.8/dist-packages/flask/app.py", line 867, in full_dispatch_request
    rv = self.dispatch_request()
  File "/usr/local/lib/python3.8/dist-packages/flask/app.py", line 852, in dispatch_request
    return self.ensure_sync(self.view_functions[rule.endpoint])(**view_args)
  File "/home/ammo/public/app.py", line 75, in register
    existing_user = execute_query('SELECT * FROM users WHERE username=%s', (username,), fetchone=True)
  File "/home/ammo/public/app.py", line 35, in execute_query
    return None
  File "/usr/local/lib/python3.8/dist-packages/mysql/connector/abstracts.py", line 1621, in __exit__
    self.close()
  File "/usr/local/lib/python3.8/dist-packages/mysql/connector/cursor.py", line 429, in close
    self._connection.handle_unread_result()
  File "/usr/local/lib/python3.8/dist-packages/mysql/connector/connection.py", line 1523, in handle_unread_result
    raise InternalError("Unread result found")
mysql.connector.errors.InternalError: Unread result found
[2023-11-30 22:33:13,104] ERROR in app: Exception on /register [POST]
Traceback (most recent call last):
  File "/home/ammo/public/app.py", line 30, in execute_query
    connection.commit()
  File "/usr/local/lib/python3.8/dist-packages/mysql/connector/connection.py", line 1263, in commit
    self._execute_query("COMMIT")
  File "/usr/local/lib/python3.8/dist-packages/mysql/connector/connection.py", line 1281, in _execute_query
    self.handle_unread_result()
  File "/usr/local/lib/python3.8/dist-packages/mysql/connector/connection.py", line 1523, in handle_unread_result
    raise InternalError("Unread result found")
mysql.connector.errors.InternalError: Unread result found

During handling of the above exception, another exception occurred:

Traceback (most recent call last):
  File "/usr/local/lib/python3.8/dist-packages/flask/app.py", line 1455, in wsgi_app
    response = self.full_dispatch_request()
  File "/usr/local/lib/python3.8/dist-packages/flask/app.py", line 869, in full_dispatch_request
    rv = self.handle_user_exception(e)
  File "/usr/local/lib/python3.8/dist-packages/flask/app.py", line 867, in full_dispatch_request
    rv = self.dispatch_request()
  File "/usr/local/lib/python3.8/dist-packages/flask/app.py", line 852, in dispatch_request
    return self.ensure_sync(self.view_functions[rule.endpoint])(**view_args)
  File "/home/ammo/public/app.py", line 75, in register
    existing_user = execute_query('SELECT * FROM users WHERE username=%s', (username,), fetchone=True)
  File "/home/ammo/public/app.py", line 35, in execute_query
    return None
  File "/usr/local/lib/python3.8/dist-packages/mysql/connector/abstracts.py", line 1621, in __exit__
    self.close()
  File "/usr/local/lib/python3.8/dist-packages/mysql/connector/cursor.py", line 429, in close
    self._connection.handle_unread_result()
  File "/usr/local/lib/python3.8/dist-packages/mysql/connector/connection.py", line 1523, in handle_unread_result
    raise InternalError("Unread result found")
mysql.connector.errors.InternalError: Unread result found
[2023-11-30 22:34:53,239] ERROR in app: Exception on /register [POST]
Traceback (most recent call last):
  File "/home/ammo/public/app.py", line 30, in execute_query
    connection.commit()
  File "/usr/local/lib/python3.8/dist-packages/mysql/connector/connection.py", line 1263, in commit
    self._execute_query("COMMIT")
  File "/usr/local/lib/python3.8/dist-packages/mysql/connector/connection.py", line 1281, in _execute_query
    self.handle_unread_result()
  File "/usr/local/lib/python3.8/dist-packages/mysql/connector/connection.py", line 1523, in handle_unread_result
    raise InternalError("Unread result found")
mysql.connector.errors.InternalError: Unread result found

During handling of the above exception, another exception occurred:

Traceback (most recent call last):
  File "/usr/local/lib/python3.8/dist-packages/flask/app.py", line 1455, in wsgi_app
    response = self.full_dispatch_request()
  File "/usr/local/lib/python3.8/dist-packages/flask/app.py", line 869, in full_dispatch_request
    rv = self.handle_user_exception(e)
  File "/usr/local/lib/python3.8/dist-packages/flask/app.py", line 867, in full_dispatch_request
    rv = self.dispatch_request()
  File "/usr/local/lib/python3.8/dist-packages/flask/app.py", line 852, in dispatch_request
    return self.ensure_sync(self.view_functions[rule.endpoint])(**view_args)
  File "/home/ammo/public/app.py", line 75, in register
    existing_user = execute_query('SELECT * FROM users WHERE username=%s', (username,), fetchone=True)
  File "/home/ammo/public/app.py", line 35, in execute_query
    return None
  File "/usr/local/lib/python3.8/dist-packages/mysql/connector/abstracts.py", line 1621, in __exit__
    self.close()
  File "/usr/local/lib/python3.8/dist-packages/mysql/connector/cursor.py", line 429, in close
    self._connection.handle_unread_result()
  File "/usr/local/lib/python3.8/dist-packages/mysql/connector/connection.py", line 1523, in handle_unread_result
    raise InternalError("Unread result found")
mysql.connector.errors.InternalError: Unread result found
[2023-12-12 19:29:44 +0000] [1915] [INFO] Starting gunicorn 21.2.0
[2023-12-12 19:29:44 +0000] [1915] [INFO] Listening at: http://127.0.0.1:5000 (1915)
[2023-12-12 19:29:44 +0000] [1915] [INFO] Using worker: sync
[2023-12-12 19:29:44 +0000] [1917] [INFO] Booting worker with pid: 1917
[2023-12-12 19:29:44 +0000] [1919] [INFO] Booting worker with pid: 1919
[2023-12-12 19:29:44 +0000] [1920] [INFO] Booting worker with pid: 1920
[2023-12-12 19:29:45 +0000] [1921] [INFO] Booting worker with pid: 1921
[2023-12-13 00:37:05 +0000] [1915] [ERROR] Worker (pid:1917) was sent SIGHUP!
[2023-12-13 00:37:05 +0000] [1915] [ERROR] Worker (pid:1919) was sent SIGHUP!
[2023-12-13 00:37:05 +0000] [1915] [ERROR] Worker (pid:1920) was sent SIGHUP!
[2023-12-13 00:37:05 +0000] [1915] [ERROR] Worker (pid:1921) was sent SIGHUP!
[2023-12-13 00:37:05 +0000] [6395] [INFO] Booting worker with pid: 6395
[2023-12-13 00:37:05 +0000] [6396] [INFO] Booting worker with pid: 6396
[2023-12-13 00:37:05 +0000] [6397] [INFO] Booting worker with pid: 6397
[2023-12-13 00:37:05 +0000] [6398] [INFO] Booting worker with pid: 6398
[2023-12-13 00:37:06 +0000] [1915] [INFO] Handling signal: hup
[2023-12-13 00:37:06 +0000] [1915] [INFO] Hang up: Master
[2023-12-13 00:37:06 +0000] [6400] [INFO] Booting worker with pid: 6400
[2023-12-13 00:37:06 +0000] [6399] [INFO] Booting worker with pid: 6399
[2023-12-13 00:37:06 +0000] [6402] [INFO] Booting worker with pid: 6402
[2023-12-13 00:37:06 +0000] [6401] [INFO] Booting worker with pid: 6401
[2023-12-13 00:37:07 +0000] [6396] [INFO] Worker exiting (pid: 6396)
[2023-12-13 00:37:07 +0000] [6397] [INFO] Worker exiting (pid: 6397)
[2023-12-13 00:37:07 +0000] [6395] [INFO] Worker exiting (pid: 6395)
[2023-12-13 00:37:07 +0000] [6398] [INFO] Worker exiting (pid: 6398)
[2023-12-13 00:37:08 +0000] [1915] [ERROR] Worker (pid:6396) was sent SIGTERM!
[2023-12-13 00:37:08 +0000] [1915] [ERROR] Worker (pid:6397) was sent SIGTERM!
[2023-12-13 00:37:08 +0000] [1915] [ERROR] Worker (pid:6398) was sent SIGTERM!
[2023-12-13 00:37:08 +0000] [1915] [ERROR] Worker (pid:6395) was sent SIGTERM!
